Workbook

Sheet Inputs
A1: Task 1.2 uncertainty budget: scenario inputs
A3: Input | B3: Value | C3: Unit | D3: Source / assumption
A4: Starting OD, C_0 | B4: 1.5 | C4: OD | D4: Scenario choice: a typical well in the observed 1.0-1.8 range (user's plates). Must be >= C_target.
A5: Target OD, C_target | B5: 1 | C5: OD | D5: Process setpoint (assignment section 1.1).
A6: Nominal transfer volume, V~_transfer | B6: 100 | C6: uL | D6: Half of the 200 uL source well (assignment section 1.1).
A7: Tip size (largest dispense) | B7: 20 | C7: uL | D7: 20 uL tip on the Flex 1-50 uL pipette (assignment section 1.1). Use 20 or 50. For the 50 uL tip, set the CV (B8) to 0.07 (50 uL tip, 1 uL row); the bias bound stays 0.08.
A8: Random error, CV | B8: 0.035 | C8: fraction | D8: Opentrons spec, 20 uL tip, 1 uL row: Random Error 3.50 % CV. A CV is one standard deviation, so u = CV (GUM 4.3.3). Applied to every dispense (20 uL tip). For the 50 uL tip use 0.07.
A9: Bias bound, a (half-width) | B9: 0.08 | C9: fraction | D9: Opentrons spec, 20 uL tip, 1 uL row: Systematic Error +/-8.00 %. Rectangular distribution, u = a/sqrt(3) (GUM 4.3.7).
A10: Correlation of transfer and dilution biases, r | B10: 1 | C10: - | D10: Assumption 3 (project document): the bias is a property of the pipette, shared by every dispense of a run, so r = +1 (GUM 5.2.2 eq. 14, F.1.2.3). Lower r to test sensitivity.
A11: Coverage factor for expanded uncertainty | B11: 2 | C11: - | D11: U = k u_c (GUM 6.2.1).
A12: Tolerance half-width | B12: 0.02 | C12: OD | D12: Normalization range 1.0 +/- 0.02 OD (assignment section 1.1).

Sheet Budget
A1: Task 1.2 uncertainty budget (GUM law of propagation, eq. 13)
A3: Derived quantities
A4: Nominal media volume, V~_d = V~_transfer (C_0/C_target - 1) | B4: =Inputs!$B$6*(Inputs!$B$4/Inputs!$B$5-1) -> 50 | C4: uL | D4: Controller's dose from the nominal mass balance (general-form note, layer 3).
A5: Media fraction, 1 - C_target/C_0 | B5: =1-Inputs!$B$5/Inputs!$B$4 -> 0.33333333 | C5: - | D5: Nominal media share of the final volume.
A6: Outer slope, C_target (1 - C_target/C_0) | B6: =Inputs!$B$5*B5 -> 0.33333333 | C6: OD | D6: Sensitivity of C_final to each step error: + for transfer, - for dilution (note 02, section 1, step 5).
A7: u(eps_random) = CV | B7: =Inputs!$B$8 -> 0.035 | C7: - | D7: Type B, GUM 4.3.3: a CV is one standard deviation.
A8: u(eps_systematic) = a / sqrt(3) | B8: =Inputs!$B$9/SQRT(3) -> 0.046188022 | C8: - | D8: Type B, rectangular distribution, GUM 4.3.7.
A9: Covariance of the bias pair, r u(eps_sys)^2 | B9: =Inputs!$B$10*B8^2 -> 0.0021333333 | C9: - | D9: GUM 5.2.2 eq. 14 rearranged; shared bias via GUM F.1.2.3.
A11: Input | B11: Step | C11: Dispense no. | D11: Nominal volume (uL) | E11: Weight w = v~/V~_step | F11: u(x_i) | G11: c_i (OD) | H11: Signed contribution, c_i u(x_i) (OD) | I11: Term in u_c^2 (OD^2) | J11: Share of u_c^2
A12: eps_random,t,1 | B12: Transfer | C12: 1 | D12: =MAX(0,MIN(Inputs!$B$7,Inputs!$B$6-(1-1)*Inputs!$B$7)) -> 20 | E12: =IF(Inputs!$B$6>0,D12/Inputs!$B$6,0) -> 0.2 | F12: =IF(D12>0,$B$7,0) -> 0.035 | G12: =$B$6*E12 -> 0.066666667 | H12: =G12*F12 -> 0.0023333333 | I12: =H12^2 -> 5.4444444e-06 | J12: =IF($I$35>0,I12/$I$35,0) -> 0.071428571
A13: eps_random,t,2 | B13: Transfer | C13: 2 | D13: =MAX(0,MIN(Inputs!$B$7,Inputs!$B$6-(2-1)*Inputs!$B$7)) -> 20 | E13: =IF(Inputs!$B$6>0,D13/Inputs!$B$6,0) -> 0.2 | F13: =IF(D13>0,$B$7,0) -> 0.035 | G13: =$B$6*E13 -> 0.066666667 | H13: =G13*F13 -> 0.0023333333 | I13: =H13^2 -> 5.4444444e-06 | J13: =IF($I$35>0,I13/$I$35,0) -> 0.071428571
A14: eps_random,t,3 | B14: Transfer | C14: 3 | D14: =MAX(0,MIN(Inputs!$B$7,Inputs!$B$6-(3-1)*Inputs!$B$7)) -> 20 | E14: =IF(Inputs!$B$6>0,D14/Inputs!$B$6,0) -> 0.2 | F14: =IF(D14>0,$B$7,0) -> 0.035 | G14: =$B$6*E14 -> 0.066666667 | H14: =G14*F14 -> 0.0023333333 | I14: =H14^2 -> 5.4444444e-06 | J14: =IF($I$35>0,I14/$I$35,0) -> 0.071428571
A15: eps_random,t,4 | B15: Transfer | C15: 4 | D15: =MAX(0,MIN(Inputs!$B$7,Inputs!$B$6-(4-1)*Inputs!$B$7)) -> 20 | E15: =IF(Inputs!$B$6>0,D15/Inputs!$B$6,0) -> 0.2 | F15: =IF(D15>0,$B$7,0) -> 0.035 | G15: =$B$6*E15 -> 0.066666667 | H15: =G15*F15 -> 0.0023333333 | I15: =H15^2 -> 5.4444444e-06 | J15: =IF($I$35>0,I15/$I$35,0) -> 0.071428571
A16: eps_random,t,5 | B16: Transfer | C16: 5 | D16: =MAX(0,MIN(Inputs!$B$7,Inputs!$B$6-(5-1)*Inputs!$B$7)) -> 20 | E16: =IF(Inputs!$B$6>0,D16/Inputs!$B$6,0) -> 0.2 | F16: =IF(D16>0,$B$7,0) -> 0.035 | G16: =$B$6*E16 -> 0.066666667 | H16: =G16*F16 -> 0.0023333333 | I16: =H16^2 -> 5.4444444e-06 | J16: =IF($I$35>0,I16/$I$35,0) -> 0.071428571
A17: eps_random,t,6 | B17: Transfer | C17: 6 | D17: =MAX(0,MIN(Inputs!$B$7,Inputs!$B$6-(6-1)*Inputs!$B$7)) -> 0 | E17: =IF(Inputs!$B$6>0,D17/Inputs!$B$6,0) -> 0 | F17: =IF(D17>0,$B$7,0) -> 0 | G17: =$B$6*E17 -> 0 | H17: =G17*F17 -> 0 | I17: =H17^2 -> 0 | J17: =IF($I$35>0,I17/$I$35,0) -> 0
A18: eps_random,t,7 | B18: Transfer | C18: 7 | D18: =MAX(0,MIN(Inputs!$B$7,Inputs!$B$6-(7-1)*Inputs!$B$7)) -> 0 | E18: =IF(Inputs!$B$6>0,D18/Inputs!$B$6,0) -> 0 | F18: =IF(D18>0,$B$7,0) -> 0 | G18: =$B$6*E18 -> 0 | H18: =G18*F18 -> 0 | I18: =H18^2 -> 0 | J18: =IF($I$35>0,I18/$I$35,0) -> 0
A19: eps_random,t,8 | B19: Transfer | C19: 8 | D19: =MAX(0,MIN(Inputs!$B$7,Inputs!$B$6-(8-1)*Inputs!$B$7)) -> 0 | E19: =IF(Inputs!$B$6>0,D19/Inputs!$B$6,0) -> 0 | F19: =IF(D19>0,$B$7,0) -> 0 | G19: =$B$6*E19 -> 0 | H19: =G19*F19 -> 0 | I19: =H19^2 -> 0 | J19: =IF($I$35>0,I19/$I$35,0) -> 0
A20: eps_random,t,9 | B20: Transfer | C20: 9 | D20: =MAX(0,MIN(Inputs!$B$7,Inputs!$B$6-(9-1)*Inputs!$B$7)) -> 0 | E20: =IF(Inputs!$B$6>0,D20/Inputs!$B$6,0) -> 0 | F20: =IF(D20>0,$B$7,0) -> 0 | G20: =$B$6*E20 -> 0 | H20: =G20*F20 -> 0 | I20: =H20^2 -> 0 | J20: =IF($I$35>0,I20/$I$35,0) -> 0
A21: eps_random,t,10 | B21: Transfer | C21: 10 | D21: =MAX(0,MIN(Inputs!$B$7,Inputs!$B$6-(10-1)*Inputs!$B$7)) -> 0 | E21: =IF(Inputs!$B$6>0,D21/Inputs!$B$6,0) -> 0 | F21: =IF(D21>0,$B$7,0) -> 0 | G21: =$B$6*E21 -> 0 | H21: =G21*F21 -> 0 | I21: =H21^2 -> 0 | J21: =IF($I$35>0,I21/$I$35,0) -> 0
A22: eps_random,d,1 | B22: Dilution | C22: 1 | D22: =MAX(0,MIN(Inputs!$B$7,$B$4-(1-1)*Inputs!$B$7)) -> 20 | E22: =IF($B$4>0,D22/$B$4,0) -> 0.4 | F22: =IF(D22>0,$B$7,0) -> 0.035 | G22: =-$B$6*E22 -> -0.13333333 | H22: =G22*F22 -> -0.0046666667 | I22: =H22^2 -> 2.1777778e-05 | J22: =IF($I$35>0,I22/$I$35,0) -> 0.28571429
A23: eps_random,d,2 | B23: Dilution | C23: 2 | D23: =MAX(0,MIN(Inputs!$B$7,$B$4-(2-1)*Inputs!$B$7)) -> 20 | E23: =IF($B$4>0,D23/$B$4,0) -> 0.4 | F23: =IF(D23>0,$B$7,0) -> 0.035 | G23: =-$B$6*E23 -> -0.13333333 | H23: =G23*F23 -> -0.0046666667 | I23: =H23^2 -> 2.1777778e-05 | J23: =IF($I$35>0,I23/$I$35,0) -> 0.28571429
A24: eps_random,d,3 | B24: Dilution | C24: 3 | D24: =MAX(0,MIN(Inputs!$B$7,$B$4-(3-1)*Inputs!$B$7)) -> 10 | E24: =IF($B$4>0,D24/$B$4,0) -> 0.2 | F24: =IF(D24>0,$B$7,0) -> 0.035 | G24: =-$B$6*E24 -> -0.066666667 | H24: =G24*F24 -> -0.0023333333 | I24: =H24^2 -> 5.4444444e-06 | J24: =IF($I$35>0,I24/$I$35,0) -> 0.071428571
A25: eps_random,d,4 | B25: Dilution | C25: 4 | D25: =MAX(0,MIN(Inputs!$B$7,$B$4-(4-1)*Inputs!$B$7)) -> 0 | E25: =IF($B$4>0,D25/$B$4,0) -> 0 | F25: =IF(D25>0,$B$7,0) -> 0 | G25: =-$B$6*E25 -> 0 | H25: =G25*F25 -> 0 | I25: =H25^2 -> 0 | J25: =IF($I$35>0,I25/$I$35,0) -> 0
A26: eps_random,d,5 | B26: Dilution | C26: 5 | D26: =MAX(0,MIN(Inputs!$B$7,$B$4-(5-1)*Inputs!$B$7)) -> 0 | E26: =IF($B$4>0,D26/$B$4,0) -> 0 | F26: =IF(D26>0,$B$7,0) -> 0 | G26: =-$B$6*E26 -> 0 | H26: =G26*F26 -> 0 | I26: =H26^2 -> 0 | J26: =IF($I$35>0,I26/$I$35,0) -> 0
A27: eps_random,d,6 | B27: Dilution | C27: 6 | D27: =MAX(0,MIN(Inputs!$B$7,$B$4-(6-1)*Inputs!$B$7)) -> 0 | E27: =IF($B$4>0,D27/$B$4,0) -> 0 | F27: =IF(D27>0,$B$7,0) -> 0 | G27: =-$B$6*E27 -> 0 | H27: =G27*F27 -> 0 | I27: =H27^2 -> 0 | J27: =IF($I$35>0,I27/$I$35,0) -> 0
A28: eps_random,d,7 | B28: Dilution | C28: 7 | D28: =MAX(0,MIN(Inputs!$B$7,$B$4-(7-1)*Inputs!$B$7)) -> 0 | E28: =IF($B$4>0,D28/$B$4,0) -> 0 | F28: =IF(D28>0,$B$7,0) -> 0 | G28: =-$B$6*E28 -> 0 | H28: =G28*F28 -> 0 | I28: =H28^2 -> 0 | J28: =IF($I$35>0,I28/$I$35,0) -> 0
A29: eps_random,d,8 | B29: Dilution | C29: 8 | D29: =MAX(0,MIN(Inputs!$B$7,$B$4-(8-1)*Inputs!$B$7)) -> 0 | E29: =IF($B$4>0,D29/$B$4,0) -> 0 | F29: =IF(D29>0,$B$7,0) -> 0 | G29: =-$B$6*E29 -> 0 | H29: =G29*F29 -> 0 | I29: =H29^2 -> 0 | J29: =IF($I$35>0,I29/$I$35,0) -> 0
A30: eps_random,d,9 | B30: Dilution | C30: 9 | D30: =MAX(0,MIN(Inputs!$B$7,$B$4-(9-1)*Inputs!$B$7)) -> 0 | E30: =IF($B$4>0,D30/$B$4,0) -> 0 | F30: =IF(D30>0,$B$7,0) -> 0 | G30: =-$B$6*E30 -> 0 | H30: =G30*F30 -> 0 | I30: =H30^2 -> 0 | J30: =IF($I$35>0,I30/$I$35,0) -> 0
A31: eps_random,d,10 | B31: Dilution | C31: 10 | D31: =MAX(0,MIN(Inputs!$B$7,$B$4-(10-1)*Inputs!$B$7)) -> 0 | E31: =IF($B$4>0,D31/$B$4,0) -> 0 | F31: =IF(D31>0,$B$7,0) -> 0 | G31: =-$B$6*E31 -> 0 | H31: =G31*F31 -> 0 | I31: =H31^2 -> 0 | J31: =IF($I$35>0,I31/$I$35,0) -> 0
A32: eps_systematic,t | B32: Transfer bias | F32: =$B$8 -> 0.046188022 | G32: =$B$6 -> 0.33333333 | H32: =G32*F32 -> 0.015396007 | I32: =H32^2 -> 0.00023703704 | J32: =IF($I$35>0,I32/$I$35,0) -> 3.1098154
A33: eps_systematic,d | B33: Dilution bias | F33: =$B$8 -> 0.046188022 | G33: =-$B$6 -> -0.33333333 | H33: =G33*F33 -> -0.015396007 | I33: =H33^2 -> 0.00023703704 | J33: =IF($I$35>0,I33/$I$35,0) -> 3.1098154
A34: Covariance of the bias pair | B34: 2 c_sys,t c_sys,d u(eps_sys,t, eps_sys,d) | I34: =2*G32*G33*$B$9 -> -0.00047407407 | J34: =IF($I$35>0,I34/$I$35,0) -> -6.2196307
A35: Total, u_c^2 | I35: =SUM(I12:I34) -> 7.6222222e-05
A36: Combined standard uncertainty, u_c (OD) | I36: =SQRT(I35) -> 0.0087305339
A38: Result (task 1.2: total and dominant terms)
A39: Combined standard uncertainty, u_c (OD) | B39: =I36 -> 0.0087305339
A40: Share of u_c^2: transfer random errors | B40: =SUM(I12:I21)/I35 -> 0.35714286
A41: Share of u_c^2: dilution random errors | B41: =SUM(I22:I31)/I35 -> 0.64285714
A42: Share of u_c^2: biases net (two variances + covariance) | B42: =(I32+I33+I34)/I35 -> 0
A43: Largest random-error term (share of u_c^2) | B43: =MAX(J12:J31) -> 0.28571429
...
